Workbook

Sheet R16b_v3p6
B1: Contact Forces Tests | C1: 9.1.0.441655 (R2016b) | F1: 42789.556 | H1: CFL v3.6
D2: Linear, No Friction | F2: Linear, Stick-Slip C | H2: Nonlin., No Friction | J2: Nonlin., Stick-Slip C
A3: # | B3: Model | C3: Stop Time | D3: # Steps | E3: Sim Time | F3: # Steps | G3: Sim Time | H3: # Steps | I3: Sim Time | J3: # Steps | K3: Sim Time
A4: 1 | B4: Collision_01_Ball_Infinite_Plane | C4: 6 | D4: 2400 | E4: 2.361 | F4: 2400 | G4: 0.203 | H4: 2400 | I4: 0.195 | J4: 2400 | K4: 0.182
A5: 2 | B5: Collision_02_Disk_Finite_Plane_Fixed | C5: 4 | D5: 674 | E5: 0.413 | F5: 959 | G5: 0.082 | H5: 731 | I5: 0.069 | J5: 1028 | K5: 0.094
A6: 3 | B6: Collision_03_Disk_Finite_Plane_Spin | C6: 1.5 | D6: 311 | E6: 0.155 | F6: 366 | G6: 0.063 | H6: 317 | I6: 0.052 | J6: 397 | K6: 0.058
A7: 4 | B7: Collision_04_Disks_in_Box | C7: 3 | D7: 3805 | E7: 1.992 | F7: 4277 | G7: 2.389 | H7: 4676 | I7: 2.844 | J7: 6400 | K7: 4.148
A8: 5 | B8: Collision_05_Disk_in_Ring | C8: 5 | D8: 2040 | E8: 0.222 | F8: 2678 | G8: 0.338 | H8: 2284 | I8: 0.196 | J8: 2932 | K8: 0.309
A9: 6 | B9: Collision_06_Catapult | C9: 1.2 | D9: 616 | E9: 0.148 | F9: 607 | G9: 0.127 | H9: 745 | I9: 0.123 | J9: 672 | K9: 0.127
A10: 7 | B10: Collision_07_Ball_Finite_Plane_Float | C10: 1.5 | D10: 200 | E10: 0.05 | F10: 207 | G10: 0.03 | H10: 213 | I10: 0.028 | J10: 221 | K10: 0.03
A11: 8 | B11: Collision_08_Compare_Forces | C11: 5 | D11: 10055 | E11: 3.036 | F11: 18563 | G11: 7.242 | H11: 12458 | I11: 5.024 | J11: 20798 | K11: 7.861
A12: 9 | B12: Friction_01_Box_on_Ramp_Constraint | C12: 10 | D12: 1211 | E12: 0.157 | F12: 1211 | G12: 0.09 | H12: 1211 | I12: 0.086 | J12: 1211 | K12: 0.089
A13: 10 | B13: Friction_02_Box_on_Ramp | C13: 10 | D13: 1301 | E13: 0.167 | F13: 1411 | G13: 0.197 | H13: 1396 | I13: 0.179 | J13: 1476 | K13: 0.194
A14: 11 | B14: Friction_03_Double_Pendulum_Constraint | C14: 45 | D14: 5538 | E14: 0.4 | F14: 5538 | G14: 0.272 | H14: 5538 | I14: 0.259 | J14: 5538 | K14: 0.249
A15: 12 | B15: Friction_04_Disk_Rolling_on_Ramp | C15: 4 | D15: 732 | E15: 0.104 | F15: 859 | G15: 0.076 | H15: 807 | I15: 0.068 | J15: 934 | K15: 0.088
... A40: 37 | B40: Gripper_2Belts | C40: 30 | D40: 5207 | E40: 5.904 | F40: 5207 | G40: 5.904 | H40: 5207 | I40: 5.904 | J40: 5207 | K40: 5.904
A41: 38 | B41: Mini Golf Hole 1 | C41: 33.72 | D41: 8856 | E41: 4.496 | F41: n/a | G41: n/a | H41: n/a | I41: n/a | J41: n/a | K41: n/a
A42: 39 | B42: Mini Golf Hole 2 | C42: 32.19 | D42: 8467 | E42: 5.198 | F42: n/a | G42: n/a | H42: n/a | I42: n/a | J42: n/a | K42: n/a
A43: 40 | B43: Mini Golf Hole 3 | C43: 59.18 | D43: 14844 | E43: 9.94 | F43: n/a | G43: n/a | H43: n/a | I43: n/a | J43: n/a | K43: n/a
A44: 41 | B44: Mini Golf Hole 4 | C44: 39.02 | D44: 11309 | E44: 8.606 | F44: n/a | G44: n/a | H44: n/a | I44: n/a | J44: n/a | K44: n/a
A45: 42 | B45: Mini Golf Hole 5 | C45: 34.68 | D45: 9052 | E45: 5.272 | F45: n/a | G45: n/a | H45: n/a | I45: n/a | J45: n/a | K45: n/a
A46: 43 | B46: Mini Golf Hole 6 | C46: 40.86 | D46: 12326 | E46: 13.325 | F46: n/a | G46: n/a | H46: n/a | I46: n/a | J46: n/a | K46: n/a
A47: 44 | B47: Mini Golf Hole 7 | C47: 41.27 | D47: 11073 | E47: 8.528 | F47: n/a | G47: n/a | H47: n/a | I47: n/a | J47: n/a | K47: n/a
A48: 45 | B48: Mini Golf Hole 8 | C48: 45.28 | D48: 11677 | E48: 14.112 | F48: n/a | G48: n/a | H48: n/a | I48: n/a | J48: n/a | K48: n/a
A49: 46 | B49: Mini Golf Hole 9 | C49: 27.71 | D49: 9011 | E49: 9.234 | F49: n/a | G49: n/a | H49: n/a | I49: n/a | J49: n/a | K49: n/a

Sheet R17a_v3p6
B1: Contact Forces Tests | C1: 9.2.0.537268 (R2017a) | F1: 42789.787 | H1: CFL v3.6
D2: Linear, No Friction | F2: Linear, Stick-Slip C | H2: Nonlin., No Friction | J2: Nonlin., Stick-Slip C
A3: # | B3: Model | C3: Stop Time | D3: # Steps | E3: Sim Time | F3: # Steps | G3: Sim Time | H3: # Steps | I3: Sim Time | J3: # Steps | K3: Sim Time
A4: 1 | B4: Collision_01_Ball_Infinite_Plane | C4: 6 | D4: 2400 | E4: 0.566 | F4: 2400 | G4: 0.206 | H4: 2400 | I4: 0.23 | J4: 2400 | K4: 0.176
A5: 2 | B5: Collision_02_Disk_Finite_Plane_Fixed | C5: 4 | D5: 674 | E5: 1.104 | F5: 959 | G5: 0.129 | H5: 731 | I5: 0.12 | J5: 1028 | K5: 0.124
A6: 3 | B6: Collision_03_Disk_Finite_Plane_Spin | C6: 1.5 | D6: 311 | E6: 0.271 | F6: 366 | G6: 0.085 | H6: 317 | I6: 0.084 | J6: 397 | K6: 0.075
A7: 4 | B7: Collision_04_Disks_in_Box | C7: 3 | D7: 3805 | E7: 2.015 | F7: 4277 | G7: 2.551 | H7: 4676 | I7: 2.649 | J7: 6400 | K7: 4.137
A8: 5 | B8: Collision_05_Disk_in_Ring | C8: 5 | D8: 2040 | E8: 0.377 | F8: 2678 | G8: 0.481 | H8: 2284 | I8: 0.354 | J8: 2932 | K8: 0.458
A9: 6 | B9: Collision_06_Catapult | C9: 1.2 | D9: 616 | E9: 0.185 | F9: 607 | G9: 0.127 | H9: 745 | I9: 0.15 | J9: 672 | K9: 0.145
A10: 7 | B10: Collision_07_Ball_Finite_Plane_Float | C10: 1.5 | D10: 200 | E10: 0.059 | F10: 207 | G10: 0.04 | H10: 213 | I10: 0.04 | J10: 221 | K10: 0.04
A11: 8 | B11: Collision_08_Compare_Forces | C11: 5 | D11: 10055 | E11: 2.865 | F11: 18563 | G11: 6.799 | H11: 12458 | I11: 4.403 | J11: 20798 | K11: 8.15
A12: 9 | B12: Friction_01_Box_on_Ramp_Constraint | C12: 10 | D12: 1211 | E12: 0.178 | F12: 1211 | G12: 0.092 | H12: 1211 | I12: 0.092 | J12: 1211 | K12: 0.092
A13: 10 | B13: Friction_02_Box_on_Ramp | C13: 10 | D13: 1301 | E13: 0.188 | F13: 1411 | G13: 0.184 | H13: 1396 | I13: 0.151 | J13: 1476 | K13: 0.197
A14: 11 | B14: Friction_03_Double_Pendulum_Constraint | C14: 45 | D14: 5538 | E14: 0.497 | F14: 5538 | G14: 0.4 | H14: 5538 | I14: 0.422 | J14: 5538 | K14: 0.412
A15: 12 | B15: Friction_04_Disk_Rolling_on_Ramp | C15: 4 | D15: 732 | E15: 0.108 | F15: 859 | G15: 0.087 | H15: 807 | I15: 0.082 | J15: 934 | K15: 0.1
... A40: 37 | B40: Gripper_2Belts | C40: 30 | D40: 5207 | E40: 5.997 | F40: 5207 | G40: 5.997 | H40: 5207 | I40: 5.997 | J40: 5207 | K40: 5.997
A41: 38 | B41: Mini Golf Hole 1 | C41: 33.72 | D41: 8856 | E41: 4.221 | F41: n/a | G41: n/a | H41: n/a | I41: n/a | J41: n/a | K41: n/a
A42: 39 | B42: Mini Golf Hole 2 | C42: 32.19 | D42: 8467 | E42: 4.885 | F42: n/a | G42: n/a | H42: n/a | I42: n/a | J42: n/a | K42: n/a
A43: 40 | B43: Mini Golf Hole 3 | C43: 59.18 | D43: 14844 | E43: 10.362 | F43: n/a | G43: n/a | H43: n/a | I43: n/a | J43: n/a | K43: n/a
A44: 41 | B44: Mini Golf Hole 4 | C44: 39.02 | D44: 11309 | E44: 7.979 | F44: n/a | G44: n/a | H44: n/a | I44: n/a | J44: n/a | K44: n/a
A45: 42 | B45: Mini Golf Hole 5 | C45: 34.68 | D45: 9052 | E45: 5.031 | F45: n/a | G45: n/a | H45: n/a | I45: n/a | J45: n/a | K45: n/a
A46: 43 | B46: Mini Golf Hole 6 | C46: 40.86 | D46: 12326 | E46: 11.838 | F46: n/a | G46: n/a | H46: n/a | I46: n/a | J46: n/a | K46: n/a
A47: 44 | B47: Mini Golf Hole 7 | C47: 41.27 | D47: 11073 | E47: 8.382 | F47: n/a | G47: n/a | H47: n/a | I47: n/a | J47: n/a | K47: n/a
A48: 45 | B48: Mini Golf Hole 8 | C48: 45.28 | D48: 12191 | E48: 13.014 | F48: n/a | G48: n/a | H48: n/a | I48: n/a | J48: n/a | K48: n/a
A49: 46 | B49: Mini Golf Hole 9 | C49: 27.71 | D49: 9011 | E49: 9.451 | F49: n/a | G49: n/a | H49: n/a | I49: n/a | J49: n/a | K49: n/a

Sheet R17a_v3p7
B1: Contact Forces Tests | C1: 9.2.0.538062 (R2017a) | F1: 42931.033 | H1: CFL v3.7
D2: Linear, No Friction | F2: Linear, Stick-Slip C | H2: Nonlin., No Friction | J2: Nonlin., Stick-Slip C
A3: # | B3: Model | C3: Stop Time | D3: # Steps | E3: Sim Time | F3: # Steps | G3: Sim Time | H3: # Steps | I3: Sim Time | J3: # Steps | K3: Sim Time
A4: 1 | B4: Collision_01_Ball_Infinite_Plane | C4: 6 | D4: 2400 | E4: 0.235 | F4: 2400 | G4: 0.183 | H4: 2400 | I4: 0.194 | J4: 2400 | K4: 0.189
A5: 2 | B5: Collision_02_Disk_Finite_Plane_Fixed | C5: 4 | D5: 674 | E5: 0.109 | F5: 959 | G5: 0.09 | H5: 731 | I5: 0.064 | J5: 1028 | K5: 0.098
A6: 3 | B6: Collision_03_Disk_Finite_Plane_Spin | C6: 1.5 | D6: 311 | E6: 0.112 | F6: 366 | G6: 0.069 | H6: 317 | I6: 0.064 | J6: 397 | K6: 0.074
A7: 4 | B7: Collision_04_Disks_in_Box | C7: 3 | D7: 3805 | E7: 1.865 | F7: 4908 | G7: 2.541 | H7: 4676 | I7: 2.542 | J7: 6075 | K7: 3.371
A8: 5 | B8: Collision_05_Disk_in_Ring | C8: 5 | D8: 2040 | E8: 0.393 | F8: 2667 | G8: 0.514 | H8: 2284 | I8: 0.373 | J8: 2900 | K8: 0.442
A9: 6 | B9: Collision_06_Catapult | C9: 1.2 | D9: 616 | E9: 0.155 | F9: 600 | G9: 0.123 | H9: 745 | I9: 0.142 | J9: 616 | K9: 0.129
A10: 7 | B10: Collision_07_Ball_Finite_Plane_Float | C10: 1.5 | D10: 200 | E10: 0.061 | F10: 207 | G10: 0.036 | H10: 213 | I10: 0.039 | J10: 221 | K10: 0.042
A11: 8 | B11: Collision_08_Compare_Forces | C11: 5 | D11: 10055 | E11: 2.651 | F11: 18721 | G11: 6.147 | H11: 12458 | I11: 3.957 | J11: 21338 | K11: 7.496
A12: 9 | B12: Friction_01_Box_on_Ramp_Constraint | C12: 10 | D12: 1211 | E12: 0.094 | F12: 1211 | G12: 0.063 | H12: 1211 | I12: 0.061 | J12: 1211 | K12: 0.062
A13: 10 | B13: Friction_02_Box_on_Ramp | C13: 10 | D13: 1301 | E13: 0.16 | F13: 1411 | G13: 0.175 | H13: 1396 | I13: 0.15 | J13: 1476 | K13: 0.194
A14: 11 | B14: Friction_03_Double_Pendulum_Constraint | C14: 45 | D14: 5538 | E14: 0.478 | F14: 5538 | G14: 0.462 | H14: 5538 | I14: 0.412 | J14: 5538 | K14: 0.422
A15: 12 | B15: Friction_04_Disk_Rolling_on_Ramp | C15: 4 | D15: 732 | E15: 0.112 | F15: 859 | G15: 0.085 | H15: 807 | I15: 0.077 | J15: 934 | K15: 0.104
... A42: 39 | B42: Gripper_2Belts | C42: 30 | D42: 5207 | E42: 5.785 | F42: 5207 | G42: 5.785 | H42: 5207 | I42: 5.785 | J42: 5207 | K42: 5.785
A43: 40 | B43: Mini Golf Hole 1 | C43: 33.72 | D43: 8856 | E43: 3.786 | F43: n/a | G43: n/a | H43: n/a | I43: n/a | J43: n/a | K43: n/a
A44: 41 | B44: Mini Golf Hole 2 | C44: 32.19 | D44: 8467 | E44: 4.875 | F44: n/a | G44: n/a | H44: n/a | I44: n/a | J44: n/a | K44: n/a
A45: 42 | B45: Mini Golf Hole 3 | C45: 59.18 | D45: 14844 | E45: 9.402 | F45: n/a | G45: n/a | H45: n/a | I45: n/a | J45: n/a | K45: n/a
A46: 43 | B46: Mini Golf Hole 4 | C46: 39.02 | D46: 11309 | E46: 7.483 | F46: n/a | G46: n/a | H46: n/a | I46: n/a | J46: n/a | K46: n/a
A47: 44 | B47: Mini Golf Hole 5 | C47: 34.68 | D47: 9052 | E47: 4.708 | F47: n/a | G47: n/a | H47: n/a | I47: n/a | J47: n/a | K47: n/a
A48: 45 | B48: Mini Golf Hole 6 | C48: 40.86 | D48: 12326 | E48: 10.798 | F48: n/a | G48: n/a | H48: n/a | I48: n/a | J48: n/a | K48: n/a
A49: 46 | B49: Mini Golf Hole 7 | C49: 41.27 | D49: 11073 | E49: 7.466 | F49: n/a | G49: n/a | H49: n/a | I49: n/a | J49: n/a | K49: n/a
A50: 47 | B50: Mini Golf Hole 8 | C50: 45.28 | D50: 12191 | E50: 12.395 | F50: n/a | G50: n/a | H50: n/a | I50: n/a | J50: n/a | K50: n/a
A51: 48 | B51: Mini Golf Hole 9 | C51: 27.71 | D51: 9011 | E51: 8.11 | F51: n/a | G51: n/a | H51: n/a | I51: n/a | J51: n/a | K51: n/a

Sheet R17b_v3p8
B1: Contact Forces Tests | C1: 9.3.0.665824 (R2017b) | F1: 42972.044 | H1: CFL v3.8
D2: Linear, No Friction | F2: Linear, Stick-Slip C | H2: Nonlin., No Friction | J2: Nonlin., Stick-Slip C
A3: # | B3: Model | C3: Stop Time | D3: # Steps | E3: Sim Time | F3: # Steps | G3: Sim Time | H3: # Steps | I3: Sim Time | J3: # Steps | K3: Sim Time
A4: 1 | B4: Collision_01_Ball_Infinite_Plane | C4: 6 | D4: 2388 | E4: 0.527 | F4: 2388 | G4: 0.24 | H4: 2388 | I4: 0.225 | J4: 2388 | K4: 0.195
A5: 2 | B5: Collision_02_Disk_Finite_Plane_Fixed | C5: 4 | D5: 674 | E5: 0.651 | F5: 959 | G5: 0.119 | H5: 731 | I5: 0.106 | J5: 1028 | K5: 0.124
A6: 3 | B6: Collision_03_Disk_Finite_Plane_Spin | C6: 1.5 | D6: 311 | E6: 0.228 | F6: 366 | G6: 0.08 | H6: 317 | I6: 0.081 | J6: 397 | K6: 0.078
A7: 4 | B7: Collision_04_Disks_in_Box | C7: 3 | D7: 3805 | E7: 2.024 | F7: 4908 | G7: 2.576 | H7: 4676 | I7: 2.97 | J7: 6075 | K7: 3.672
A8: 5 | B8: Collision_05_Disk_in_Ring | C8: 5 | D8: 2040 | E8: 0.394 | F8: 2667 | G8: 0.413 | H8: 2284 | I8: 0.429 | J8: 2900 | K8: 0.471
A9: 6 | B9: Collision_06_Catapult | C9: 1.2 | D9: 613 | E9: 0.183 | F9: 603 | G9: 0.139 | H9: 743 | I9: 0.147 | J9: 587 | K9: 0.136
A10: 7 | B10: Collision_07_Ball_Finite_Plane_Float | C10: 1.5 | D10: 200 | E10: 0.071 | F10: 207 | G10: 0.046 | H10: 213 | I10: 0.046 | J10: 221 | K10: 0.047
A11: 8 | B11: Collision_08_Compare_Forces | C11: 5 | D11: 10055 | E11: 2.875 | F11: 18721 | G11: 7.667 | H11: 12458 | I11: 4.27 | J11: 21338 | K11: 7.774
A12: 9 | B12: Friction_01_Box_on_Ramp_Constraint | C12: 10 | D12: 1211 | E12: 0.133 | F12: 1211 | G12: 0.081 | H12: 1211 | I12: 0.074 | J12: 1211 | K12: 0.072
A13: 10 | B13: Friction_02_Box_on_Ramp | C13: 10 | D13: 1301 | E13: 0.186 | F13: 1411 | G13: 0.199 | H13: 1396 | I13: 0.168 | J13: 1476 | K13: 0.214
A14: 11 | B14: Friction_03_Double_Pendulum_Constraint | C14: 45 | D14: 5538 | E14: 0.533 | F14: 5538 | G14: 0.47 | H14: 5538 | I14: 0.434 | J14: 5538 | K14: 0.443
A15: 12 | B15: Friction_04_Disk_Rolling_on_Ramp | C15: 4 | D15: 732 | E15: 0.131 | F15: 859 | G15: 0.097 | H15: 807 | I15: 0.083 | J15: 934 | K15: 0.103
... A42: 39 | B42: Gripper_2Belts | C42: 30 | D42: 5207 | E42: 5.877 | F42: 5207 | G42: 5.877 | H42: 5207 | I42: 5.877 | J42: 5207 | K42: 5.877
A43: 40 | B43: Mini Golf Hole 1 | C43: 33.72 | D43: 8856 | E43: 3.842 | F43: n/a | G43: n/a | H43: n/a | I43: n/a | J43: n/a | K43: n/a
A44: 41 | B44: Mini Golf Hole 2 | C44: 32.19 | D44: 8467 | E44: 4.618 | F44: n/a | G44: n/a | H44: n/a | I44: n/a | J44: n/a | K44: n/a
A45: 42 | B45: Mini Golf Hole 3 | C45: 59.18 | D45: 14844 | E45: 9.289 | F45: n/a | G45: n/a | H45: n/a | I45: n/a | J45: n/a | K45: n/a
A46: 43 | B46: Mini Golf Hole 4 | C46: 39.02 | D46: 11309 | E46: 7.031 | F46: n/a | G46: n/a | H46: n/a | I46: n/a | J46: n/a | K46: n/a
A47: 44 | B47: Mini Golf Hole 5 | C47: 34.68 | D47: 9052 | E47: 4.637 | F47: n/a | G47: n/a | H47: n/a | I47: n/a | J47: n/a | K47: n/a
A48: 45 | B48: Mini Golf Hole 6 | C48: 40.86 | D48: 12326 | E48: 10.936 | F48: n/a | G48: n/a | H48: n/a | I48: n/a | J48: n/a | K48: n/a
A49: 46 | B49: Mini Golf Hole 7 | C49: 41.27 | D49: 11073 | E49: 7.434 | F49: n/a | G49: n/a | H49: n/a | I49: n/a | J49: n/a | K49: n/a
A50: 47 | B50: Mini Golf Hole 8 | C50: 45.28 | D50: 12191 | E50: 11.994 | F50: n/a | G50: n/a | H50: n/a | I50: n/a | J50: n/a | K50: n/a
A51: 48 | B51: Mini Golf Hole 9 | C51: 27.71 | D51: 9011 | E51: 8.286 | F51: n/a | G51: n/a | H51: n/a | I51: n/a | J51: n/a | K51: n/a

Sheet R17b_v3p9
B1: Contact Forces Tests | C1: 9.3.0.701794 (R2017b) | F1: 28-Dec-2017 17:35:53 | H1: CFL v3.9
D2: Linear, No Friction | F2: Linear, Stick-Slip C | H2: Nonlin., No Friction | J2: Nonlin., Stick-Slip C
A3: # | B3: Model | C3: Stop Time | D3: # Steps | E3: Sim Time | F3: # Steps | G3: Sim Time | H3: # Steps | I3: Sim Time | J3: # Steps | K3: Sim Time
A4: 1 | B4: Collision_01_Ball_Infinite_Plane | C4: 6 | D4: 2388 | E4: 0.296 | F4: 2388 | G4: 0.22 | H4: 2388 | I4: 0.21 | J4: 2388 | K4: 0.201
A5: 2 | B5: Collision_02_Disk_Finite_Plane_Fixed | C5: 4 | D5: 674 | E5: 0.15 | F5: 959 | G5: 0.111 | H5: 731 | I5: 0.077 | J5: 1028 | K5: 0.121
A6: 3 | B6: Collision_03_Disk_Finite_Plane_Spin | C6: 1.5 | D6: 311 | E6: 0.177 | F6: 366 | G6: 0.08 | H6: 317 | I6: 0.074 | J6: 397 | K6: 0.083
A7: 4 | B7: Collision_04_Disks_in_Box | C7: 3 | D7: 3805 | E7: 2.23 | F7: 4908 | G7: 3.095 | H7: 4676 | I7: 3.097 | J7: 6075 | K7: 4.043
A8: 5 | B8: Collision_05_Disk_in_Ring | C8: 5 | D8: 2040 | E8: 0.459 | F8: 2667 | G8: 0.492 | H8: 2284 | I8: 0.449 | J8: 2900 | K8: 0.571
A9: 6 | B9: Collision_06_Catapult | C9: 1.2 | D9: 613 | E9: 0.213 | F9: 603 | G9: 0.16 | H9: 743 | I9: 0.164 | J9: 587 | K9: 0.152
A10: 7 | B10: Collision_07_Ball_Finite_Plane_Float | C10: 1.5 | D10: 200 | E10: 0.08 | F10: 207 | G10: 0.046 | H10: 213 | I10: 0.046 | J10: 221 | K10: 0.05
A11: 8 | B11: Collision_08_Compare_Forces | C11: 5 | D11: 10055 | E11: 3.51 | F11: 18721 | G11: 6.894 | H11: 12458 | I11: 4.645 | J11: 21338 | K11: 8.703
A12: 9 | B12: Friction_01_Box_on_Ramp_Constraint | C12: 10 | D12: 1211 | E12: 0.138 | F12: 1211 | G12: 0.073 | H12: 1211 | I12: 0.074 | J12: 1211 | K12: 0.154
A13: 10 | B13: Friction_02_Box_on_Ramp | C13: 10 | D13: 1301 | E13: 0.212 | F13: 1411 | G13: 0.24 | H13: 1396 | I13: 0.184 | J13: 1476 | K13: 0.247
A14: 11 | B14: Friction_03_Double_Pendulum_Constraint | C14: 45 | D14: 5538 | E14: 0.583 | F14: 5538 | G14: 0.524 | H14: 5538 | I14: 0.537 | J14: 5538 | K14: 0.589
A15: 12 | B15: Friction_04_Disk_Rolling_on_Ramp | C15: 4 | D15: 732 | E15: 0.165 | F15: 859 | G15: 0.104 | H15: 807 | I15: 0.098 | J15: 934 | K15: 0.122
... A44: 41 | B44: Gripper_2Belts | C44: 30 | D44: 4891 | E44: 6.52 | F44: 4891 | G44: 6.667 | H44: 4891 | I44: 6.484 | J44: 4891 | K44: 6.421
A45: 42 | B45: Mini Golf Hole 1 | C45: 33.72 | D45: 8856 | E45: 4.607 | F45: n/a | G45: n/a | H45: n/a | I45: n/a | J45: n/a | K45: n/a
A46: 43 | B46: Mini Golf Hole 2 | C46: 32.19 | D46: 8467 | E46: 5.353 | F46: n/a | G46: n/a | H46: n/a | I46: n/a | J46: n/a | K46: n/a
A47: 44 | B47: Mini Golf Hole 3 | C47: 59.18 | D47: 14844 | E47: 10.523 | F47: n/a | G47: n/a | H47: n/a | I47: n/a | J47: n/a | K47: n/a
A48: 45 | B48: Mini Golf Hole 4 | C48: 39.02 | D48: 11309 | E48: 8.004 | F48: n/a | G48: n/a | H48: n/a | I48: n/a | J48: n/a | K48: n/a
A49: 46 | B49: Mini Golf Hole 5 | C49: 34.68 | D49: 9052 | E49: 5.568 | F49: n/a | G49: n/a | H49: n/a | I49: n/a | J49: n/a | K49: n/a
A50: 47 | B50: Mini Golf Hole 6 | C50: 40.86 | D50: 12326 | E50: 11.386 | F50: n/a | G50: n/a | H50: n/a | I50: n/a | J50: n/a | K50: n/a
A51: 48 | B51: Mini Golf Hole 7 | C51: 41.27 | D51: 11073 | E51: 8.462 | F51: n/a | G51: n/a | H51: n/a | I51: n/a | J51: n/a | K51: n/a
A52: 49 | B52: Mini Golf Hole 8 | C52: 45.28 | D52: 12191 | E52: 13.172 | F52: n/a | G52: n/a | H52: n/a | I52: n/a | J52: n/a | K52: n/a
A53: 50 | B53: Mini Golf Hole 9 | C53: 27.71 | D53: 9011 | E53: 8.884 | F53: n/a | G53: n/a | H53: n/a | I53: n/a | J53: n/a | K53: n/a

Sheet R18a_v3p10
B1: Contact Forces Tests | C1: 9.4.0.798023 (R2018a) | F1: 43147.305 | H1: CFL v3.10
D2: Linear, No Friction | F2: Linear, Stick-Slip C | H2: Nonlin., No Friction | J2: Nonlin., Stick-Slip C
A3: # | B3: Model | C3: Stop Time | D3: # Steps | E3: Sim Time | F3: # Steps | G3: Sim Time | H3: # Steps | I3: Sim Time | J3: # Steps | K3: Sim Time
A4: 1 | B4: Collision_01_Ball_Infinite_Plane | C4: 6 | D4: 2388 | E4: 0.604 | F4: 2388 | G4: 0.225 | H4: 2388 | I4: 0.233 | J4: 2388 | K4: 0.209
A5: 2 | B5: Collision_02_Disk_Finite_Plane_Fixed | C5: 4 | D5: 669 | E5: 0.975 | F5: 929 | G5: 0.169 | H5: 718 | I5: 0.124 | J5: 1020 | K5: 0.149
A6: 3 | B6: Collision_03_Disk_Finite_Plane_Spin | C6: 1.5 | D6: 298 | E6: 0.467 | F6: 370 | G6: 0.083 | H6: 317 | I6: 0.078 | J6: 398 | K6: 0.082
A7: 4 | B7: Collision_04_Disks_in_Box | C7: 3 | D7: 3726 | E7: 2.123 | F7: 4928 | G7: 2.711 | H7: 5039 | I7: 2.748 | J7: 6295 | K7: 3.8
A8: 5 | B8: Collision_05_Disk_in_Ring | C8: 5 | D8: 2096 | E8: 0.409 | F8: 2794 | G8: 0.476 | H8: 2425 | I8: 0.382 | J8: 3210 | K8: 0.473
A9: 6 | B9: Collision_06_Catapult | C9: 1.2 | D9: 612 | E9: 0.275 | F9: 579 | G9: 0.156 | H9: 747 | I9: 0.199 | J9: 602 | K9: 0.16
A10: 7 | B10: Collision_07_Ball_Finite_Plane_Float | C10: 1.5 | D10: 210 | E10: 0.154 | F10: 213 | G10: 0.062 | H10: 221 | I10: 0.058 | J10: 223 | K10: 0.065
A11: 8 | B11: Collision_08_Compare_Forces | C11: 5 | D11: 9225 | E11: 3.02 | F11: 17963 | G11: 6.678 | H11: 10816 | I11: 4.337 | J11: 21376 | K11: 8.829
A12: 9 | B12: Friction_01_Box_on_Ramp_Constraint | C12: 10 | D12: 1211 | E12: 0.117 | F12: 1211 | G12: 0.075 | H12: 1211 | I12: 0.074 | J12: 1211 | K12: 0.076
A13: 10 | B13: Friction_02_Box_on_Ramp | C13: 10 | D13: 1303 | E13: 0.312 | F13: 1444 | G13: 0.218 | H13: 1397 | I13: 0.18 | J13: 1516 | K13: 0.226
A14: 11 | B14: Friction_03_Double_Pendulum_Constraint | C14: 45 | D14: 5568 | E14: 0.465 | F14: 5568 | G14: 0.464 | H14: 5568 | I14: 0.428 | J14: 5568 | K14: 0.404
A15: 12 | B15: Friction_04_Disk_Rolling_on_Ramp | C15: 4 | D15: 721 | E15: 0.226 | F15: 860 | G15: 0.109 | H15: 800 | I15: 0.096 | J15: 941 | K15: 0.118
... A44: 41 | B44: Gripper_2Belts | C44: 30 | D44: 4779 | E44: 5.582 | F44: 4779 | G44: 5.278 | H44: 4779 | I44: 5.127 | J44: 4779 | K44: 5.463
A45: 42 | B45: Mini Golf Hole 1 | C45: 33.72 | D45: 8738 | E45: 4.219 | F45: n/a | G45: n/a | H45: n/a | I45: n/a | J45: n/a | K45: n/a
A46: 43 | B46: Mini Golf Hole 2 | C46: 32.19 | D46: 8588 | E46: 4.871 | F46: n/a | G46: n/a | H46: n/a | I46: n/a | J46: n/a | K46: n/a
A47: 44 | B47: Mini Golf Hole 3 | C47: 59.18 | D47: 15259 | E47: 9.939 | F47: n/a | G47: n/a | H47: n/a | I47: n/a | J47: n/a | K47: n/a
A48: 45 | B48: Mini Golf Hole 4 | C48: 39.01 | D48: 11323 | E48: 7.579 | F48: n/a | G48: n/a | H48: n/a | I48: n/a | J48: n/a | K48: n/a
A49: 46 | B49: Mini Golf Hole 5 | C49: 34.7 | D49: 9224 | E49: 4.989 | F49: n/a | G49: n/a | H49: n/a | I49: n/a | J49: n/a | K49: n/a
A50: 47 | B50: Mini Golf Hole 6 | C50: 40.82 | D50: 11986 | E50: 11.239 | F50: n/a | G50: n/a | H50: n/a | I50: n/a | J50: n/a | K50: n/a
A51: 48 | B51: Mini Golf Hole 7 | C51: 41.27 | D51: 11451 | E51: 8.15 | F51: n/a | G51: n/a | H51: n/a | I51: n/a | J51: n/a | K51: n/a
A52: 49 | B52: Mini Golf Hole 8 | C52: 45.28 | D52: 12026 | E52: 13.05 | F52: n/a | G52: n/a | H52: n/a | I52: n/a | J52: n/a | K52: n/a
A53: 50 | B53: Mini Golf Hole 9 | C53: 27.71 | D53: 8687 | E53: 8.289 | F53: n/a | G53: n/a | H53: n/a | I53: n/a | J53: n/a | K53: n/a

Sheet R18a_v4p0
B1: Contact Forces Tests | C1: 9.4.0.813654 (R2018a) | F1: 43167.999 | H1: CFL v4.0
D2: Linear, No Friction | F2: Linear, Stick-Slip C | H2: Nonlin., No Friction | J2: Nonlin., Stick-Slip C
A3: # | B3: Model | C3: Stop Time | D3: # Steps | E3: Sim Time | F3: # Steps | G3: Sim Time | H3: # Steps | I3: Sim Time | J3: # Steps | K3: Sim Time
A4: 1 | B4: Collision_01_Ball_Infinite_Plane | C4: 6 | D4: 2388 | E4: 0.443 | F4: 2388 | G4: 0.18 | H4: 2388 | I4: 0.192 | J4: 2388 | K4: 0.152
A5: 2 | B5: Collision_02_Disk_Finite_Plane_Fixed | C5: 4 | D5: 669 | E5: 0.528 | F5: 929 | G5: 0.291 | H5: 718 | I5: 0.109 | J5: 1020 | K5: 0.108
A6: 3 | B6: Collision_03_Disk_Finite_Plane_Spin | C6: 1.5 | D6: 298 | E6: 0.215 | F6: 370 | G6: 0.072 | H6: 317 | I6: 0.064 | J6: 398 | K6: 0.068
A7: 4 | B7: Collision_04_Disks_in_Box | C7: 3 | D7: 3726 | E7: 1.79 | F7: 4928 | G7: 2.54 | H7: 5039 | I7: 2.706 | J7: 6295 | K7: 3.821
A8: 5 | B8: Collision_05_Disk_in_Ring | C8: 5 | D8: 2096 | E8: 0.268 | F8: 2794 | G8: 0.448 | H8: 2425 | I8: 0.323 | J8: 3210 | K8: 0.447
A9: 6 | B9: Collision_06_Catapult | C9: 1.2 | D9: 612 | E9: 0.331 | F9: 579 | G9: 0.282 | H9: 747 | I9: 0.27 | J9: 602 | K9: 0.295
A10: 7 | B10: Collision_07_Ball_Finite_Plane_Float | C10: 1.5 | D10: 210 | E10: 0.23 | F10: 213 | G10: 0.197 | H10: 221 | I10: 0.188 | J10: 223 | K10: 0.216
A11: 8 | B11: Collision_08_Compare_Forces | C11: 5 | D11: 9225 | E11: 5.601 | F11: 17963 | G11: 5.618 | H11: 10816 | I11: 3.132 | J11: 21376 | K11: 6.274
A12: 9 | B12: Friction_01_Box_on_Ramp_Constraint | C12: 10 | D12: 1211 | E12: 0.098 | F12: 1211 | G12: 0.06 | H12: 1211 | I12: 0.06 | J12: 1211 | K12: 0.061
A13: 10 | B13: Friction_02_Box_on_Ramp | C13: 10 | D13: 1303 | E13: 0.196 | F13: 1444 | G13: 0.175 | H13: 1397 | I13: 0.141 | J13: 1516 | K13: 0.185
A14: 11 | B14: Friction_03_Double_Pendulum_Constraint | C14: 45 | D14: 5568 | E14: 0.291 | F14: 5568 | G14: 0.396 | H14: 5568 | I14: 0.323 | J14: 5568 | K14: 0.387
A15: 12 | B15: Friction_04_Disk_Rolling_on_Ramp | C15: 4 | D15: 721 | E15: 0.15 | F15: 860 | G15: 0.087 | H15: 800 | I15: 0.078 | J15: 941 | K15: 0.091
... A46: 43 | B46: sm_tread_drive | C46: 8.5 | D46: 2480 | E46: 16.857 | F46: 2480 | G46: 16.431 | H46: 2480 | I46: 16.655 | J46: 2480 | K46: 32.029
A47: 44 | B47: Mini Golf Hole 1 | C47: 33.72 | D47: 8738 | E47: 4.307 | F47: n/a | G47: n/a | H47: n/a | I47: n/a | J47: n/a | K47: n/a
A48: 45 | B48: Mini Golf Hole 2 | C48: 32.19 | D48: 8588 | E48: 4.084 | F48: n/a | G48: n/a | H48: n/a | I48: n/a | J48: n/a | K48: n/a
A49: 46 | B49: Mini Golf Hole 3 | C49: 59.18 | D49: 15259 | E49: 8.457 | F49: n/a | G49: n/a | H49: n/a | I49: n/a | J49: n/a | K49: n/a
A50: 47 | B50: Mini Golf Hole 4 | C50: 39.01 | D50: 11323 | E50: 6.333 | F50: n/a | G50: n/a | H50: n/a | I50: n/a | J50: n/a | K50: n/a
A51: 48 | B51: Mini Golf Hole 5 | C51: 34.7 | D51: 9224 | E51: 4.211 | F51: n/a | G51: n/a | H51: n/a | I51: n/a | J51: n/a | K51: n/a
A52: 49 | B52: Mini Golf Hole 6 | C52: 40.82 | D52: 11986 | E52: 9.708 | F52: n/a | G52: n/a | H52: n/a | I52: n/a | J52: n/a | K52: n/a
A53: 50 | B53: Mini Golf Hole 7 | C53: 41.27 | D53: 11451 | E53: 7.079 | F53: n/a | G53: n/a | H53: n/a | I53: n/a | J53: n/a | K53: n/a
A54: 51 | B54: Mini Golf Hole 8 | C54: 45.28 | D54: 12026 | E54: 10.783 | F54: n/a | G54: n/a | H54: n/a | I54: n/a | J54: n/a | K54: n/a
A55: 52 | B55: Mini Golf Hole 9 | C55: 27.71 | D55: 8687 | E55: 7.152 | F55: n/a | G55: n/a | H55: n/a | I55: n/a | J55: n/a | K55: n/a

Sheet R18b_bash_v4p1
B1: Contact Forces Tests | C1: 9.5.0.882065 (R2018b) Prerelease | F1: 43266.518 | H1: CFL v4.1
D2: Linear, No Friction | F2: Linear, Stick-Slip C | H2: Nonlin., No Friction | J2: Nonlin., Stick-Slip C
A3: # | B3: Model | C3: Stop Time | D3: # Steps | E3: Sim Time | F3: # Steps | G3: Sim Time | H3: # Steps | I3: Sim Time | J3: # Steps | K3: Sim Time
A4: 1 | B4: Collision_01_Ball_Infinite_Plane | C4: 6 | D4: 2388 | E4: 0.549 | F4: 2388 | G4: 0.203 | H4: 2388 | I4: 0.222 | J4: 2388 | K4: 0.187
A5: 2 | B5: Collision_02_Disk_Finite_Plane_Fixed | C5: 4 | D5: 669 | E5: 0.677 | F5: 935 | G5: 0.13 | H5: 718 | I5: 0.147 | J5: 1020 | K5: 0.129
A6: 3 | B6: Collision_03_Disk_Finite_Plane_Spin | C6: 1.5 | D6: 298 | E6: 0.281 | F6: 370 | G6: 0.106 | H6: 317 | I6: 0.087 | J6: 398 | K6: 0.095
A7: 4 | B7: Collision_04_Disks_in_Box | C7: 3 | D7: 3726 | E7: 2.21 | F7: 4928 | G7: 2.938 | H7: 5039 | I7: 2.951 | J7: 6295 | K7: 4.447
A8: 5 | B8: Collision_05_Disk_in_Ring | C8: 5 | D8: 2071 | E8: 0.394 | F8: 2660 | G8: 0.48 | H8: 2276 | I8: 0.303 | J8: 2954 | K8: 0.426
A9: 6 | B9: Collision_06_Catapult | C9: 1.2 | D9: 612 | E9: 0.258 | F9: 579 | G9: 0.156 | H9: 747 | I9: 0.193 | J9: 602 | K9: 0.168
A10: 7 | B10: Collision_07_Ball_Finite_Plane_Float | C10: 1.5 | D10: 210 | E10: 0.126 | F10: 213 | G10: 0.066 | H10: 221 | I10: 0.059 | J10: 223 | K10: 0.065
A11: 8 | B11: Collision_08_Compare_Forces | C11: 5 | D11: 9225 | E11: 3.484 | F11: 17963 | G11: 6.349 | H11: 10816 | I11: 3.827 | J11: 21376 | K11: 8.004
A12: 9 | B12: Friction_01_Box_on_Ramp_Constraint | C12: 10 | D12: 1211 | E12: 0.116 | F12: 1211 | G12: 0.107 | H12: 1211 | I12: 0.074 | J12: 1211 | K12: 0.077
A13: 10 | B13: Friction_02_Box_on_Ramp | C13: 10 | D13: 1303 | E13: 0.256 | F13: 1444 | G13: 0.216 | H13: 1397 | I13: 0.225 | J13: 1516 | K13: 0.234
A14: 11 | B14: Friction_03_Double_Pendulum_Constraint | C14: 45 | D14: 5568 | E14: 0.488 | F14: 5568 | G14: 0.404 | H14: 5568 | I14: 0.384 | J14: 5568 | K14: 0.38
A15: 12 | B15: Friction_04_Disk_Rolling_on_Ramp | C15: 4 | D15: 721 | E15: 0.217 | F15: 860 | G15: 0.118 | H15: 800 | I15: 0.1 | J15: 989 | K15: 0.129
... A46: 43 | B46: sm_tread_drive | C46: 50 | D46: 5515 | E46: 3.516 | F46: 9462 | G46: 8.419 | H46: 5558 | I46: 3.784 | J46: 9667 | K46: 8.737
A47: 44 | B47: Mini Golf Hole 1 | C47: 33.72 | D47: 9375 | E47: 6.078 | F47: n/a | G47: n/a | H47: n/a | I47: n/a | J47: n/a | K47: n/a
A48: 45 | B48: Mini Golf Hole 2 | C48: 32.19 | D48: 8828 | E48: 5.847 | F48: n/a | G48: n/a | H48: n/a | I48: n/a | J48: n/a | K48: n/a
A49: 46 | B49: Mini Golf Hole 3 | C49: 59.18 | D49: 15140 | E49: 11.431 | F49: n/a | G49: n/a | H49: n/a | I49: n/a | J49: n/a | K49: n/a
A50: 47 | B50: Mini Golf Hole 4 | C50: 39.02 | D50: 11499 | E50: 8.695 | F50: n/a | G50: n/a | H50: n/a | I50: n/a | J50: n/a | K50: n/a
A51: 48 | B51: Mini Golf Hole 5 | C51: 34.68 | D51: 9443 | E51: 9.192 | F51: n/a | G51: n/a | H51: n/a | I51: n/a | J51: n/a | K51: n/a
A52: 49 | B52: Mini Golf Hole 6 | C52: 40.82 | D52: 11825 | E52: 19.39 | F52: n/a | G52: n/a | H52: n/a | I52: n/a | J52: n/a | K52: n/a
A53: 50 | B53: Mini Golf Hole 7 | C53: 41.28 | D53: 11517 | E53: 12.224 | F53: n/a | G53: n/a | H53: n/a | I53: n/a | J53: n/a | K53: n/a
A54: 51 | B54: Mini Golf Hole 8 | C54: 45.27 | D54: 12245 | E54: 25.14 | F54: n/a | G54: n/a | H54: n/a | I54: n/a | J54: n/a | K54: n/a
A55: 52 | B55: Mini Golf Hole 9 | C55: 27.71 | D55: 8945 | E55: 13.165 | F55: n/a | G55: n/a | H55: n/a | I55: n/a | J55: n/a | K55: n/a

Sheet R18b_v4p1
B1: Contact Forces Tests | C1: 9.5.0.944444 (R2018b) | F1: 43354.271 | H1: CFL v4.1
D2: Linear, No Friction | F2: Linear, Stick-Slip C | H2: Nonlin., No Friction | J2: Nonlin., Stick-Slip C
A3: # | B3: Model | C3: Stop Time | D3: # Steps | E3: Sim Time | F3: # Steps | G3: Sim Time | H3: # Steps | I3: Sim Time | J3: # Steps | K3: Sim Time
A4: 1 | B4: Collision_01_Ball_Infinite_Plane | C4: 6 | D4: 2388 | E4: 0.989 | F4: 2388 | G4: 0.16 | H4: 2388 | I4: 0.138 | J4: 2388 | K4: 0.155
A5: 2 | B5: Collision_02_Disk_Finite_Plane_Fixed | C5: 4 | D5: 669 | E5: 0.636 | F5: 935 | G5: 0.107 | H5: 718 | I5: 0.124 | J5: 1020 | K5: 0.107
A6: 3 | B6: Collision_03_Disk_Finite_Plane_Spin | C6: 1.5 | D6: 298 | E6: 0.235 | F6: 370 | G6: 0.077 | H6: 317 | I6: 0.071 | J6: 398 | K6: 0.088
A7: 4 | B7: Collision_04_Disks_in_Box | C7: 3 | D7: 3726 | E7: 1.871 | F7: 4928 | G7: 2.57 | H7: 5039 | I7: 2.557 | J7: 6295 | K7: 3.52
A8: 5 | B8: Collision_05_Disk_in_Ring | C8: 5 | D8: 2071 | E8: 0.292 | F8: 2660 | G8: 0.338 | H8: 2276 | I8: 0.238 | J8: 2954 | K8: 0.332
A9: 6 | B9: Collision_06_Catapult | C9: 1.2 | D9: 612 | E9: 0.226 | F9: 579 | G9: 0.12 | H9: 747 | I9: 0.133 | J9: 602 | K9: 0.142
A10: 7 | B10: Collision_07_Ball_Finite_Plane_Float | C10: 1.5 | D10: 210 | E10: 0.159 | F10: 213 | G10: 0.052 | H10: 221 | I10: 0.051 | J10: 223 | K10: 0.051
A11: 8 | B11: Collision_08_Compare_Forces | C11: 5 | D11: 9225 | E11: 2.633 | F11: 17963 | G11: 5.128 | H11: 10816 | I11: 3.343 | J11: 21376 | K11: 6.5
A12: 9 | B12: Friction_01_Box_on_Ramp_Constraint | C12: 10 | D12: 1211 | E12: 0.102 | F12: 1211 | G12: 0.115 | H12: 1211 | I12: 0.063 | J12: 1211 | K12: 0.075
A13: 10 | B13: Friction_02_Box_on_Ramp | C13: 10 | D13: 1303 | E13: 0.255 | F13: 1444 | G13: 0.19 | H13: 1397 | I13: 0.169 | J13: 1516 | K13: 0.263
A14: 11 | B14: Friction_03_Double_Pendulum_Constraint | C14: 45 | D14: 5568 | E14: 0.308 | F14: 5568 | G14: 0.419 | H14: 5568 | I14: 0.357 | J14: 5568 | K14: 0.377
A15: 12 | B15: Friction_04_Disk_Rolling_on_Ramp | C15: 4 | D15: 721 | E15: 0.184 | F15: 860 | G15: 0.085 | H15: 800 | I15: 0.082 | J15: 989 | K15: 0.105
... A46: 43 | B46: sm_tread_drive | C46: 50 | D46: 5515 | E46: 3.717 | F46: 9462 | G46: 6.949 | H46: 5558 | I46: 3.22 | J46: 9667 | K46: 7.325
A47: 44 | B47: Mini Golf Hole 1 | C47: 33.72 | D47: 9375 | E47: 5.286 | F47: n/a | G47: n/a | H47: n/a | I47: n/a | J47: n/a | K47: n/a
A48: 45 | B48: Mini Golf Hole 2 | C48: 32.19 | D48: 8828 | E48: 5.021 | F48: n/a | G48: n/a | H48: n/a | I48: n/a | J48: n/a | K48: n/a
A49: 46 | B49: Mini Golf Hole 3 | C49: 59.18 | D49: 15140 | E49: 11.003 | F49: n/a | G49: n/a | H49: n/a | I49: n/a | J49: n/a | K49: n/a
A50: 47 | B50: Mini Golf Hole 4 | C50: 39.02 | D50: 11499 | E50: 7.741 | F50: n/a | G50: n/a | H50: n/a | I50: n/a | J50: n/a | K50: n/a
A51: 48 | B51: Mini Golf Hole 5 | C51: 34.68 | D51: 9443 | E51: 5.158 | F51: n/a | G51: n/a | H51: n/a | I51: n/a | J51: n/a | K51: n/a
A52: 49 | B52: Mini Golf Hole 6 | C52: 40.82 | D52: 11825 | E52: 11.681 | F52: n/a | G52: n/a | H52: n/a | I52: n/a | J52: n/a | K52: n/a
A53: 50 | B53: Mini Golf Hole 7 | C53: 41.28 | D53: 11517 | E53: 10.426 | F53: n/a | G53: n/a | H53: n/a | I53: n/a | J53: n/a | K53: n/a
A54: 51 | B54: Mini Golf Hole 8 | C54: 45.27 | D54: 12245 | E54: 14.163 | F54: n/a | G54: n/a | H54: n/a | I54: n/a | J54: n/a | K54: n/a
A55: 52 | B55: Mini Golf Hole 9 | C55: 27.71 | D55: 8945 | E55: 8.551 | F55: n/a | G55: n/a | H55: n/a | I55: n/a | J55: n/a | K55: n/a

Sheet R19a_v4p1
B1: Contact Forces Tests | C1: 9.6.0.1072779 (R2019a) | F1: 19-Mar-2019 07:07:34 | H1: CFL v4.1
D2: Linear, No Friction | F2: Linear, Stick-Slip C | H2: Nonlin., No Friction | J2: Nonlin., Stick-Slip C
A3: # | B3: Model | C3: Stop Time | D3: # Steps | E3: Sim Time | F3: # Steps | G3: Sim Time | H3: # Steps | I3: Sim Time | J3: # Steps | K3: Sim Time
A4: 1 | B4: Collision_01_Ball_Infinite_Plane | C4: 6 | D4: 2388 | E4: 1.178 | F4: 2388 | G4: 0.394 | H4: 2388 | I4: 0.473 | J4: 2388 | K4: 0.329
A5: 2 | B5: Collision_02_Disk_Finite_Plane_Fixed | C5: 4 | D5: 669 | E5: 0.557 | F5: 935 | G5: 0.177 | H5: 718 | I5: 0.148 | J5: 1020 | K5: 0.159
A6: 3 | B6: Collision_03_Disk_Finite_Plane_Spin | C6: 1.5 | D6: 298 | E6: 0.295 | F6: 370 | G6: 0.106 | H6: 317 | I6: 0.071 | J6: 398 | K6: 0.076
A7: 4 | B7: Collision_04_Disks_in_Box | C7: 3 | D7: 3726 | E7: 4.08 | F7: 4928 | G7: 5.1 | H7: 5039 | I7: 3.107 | J7: 6295 | K7: 4.053
A8: 5 | B8: Collision_05_Disk_in_Ring | C8: 5 | D8: 2071 | E8: 0.37 | F8: 2660 | G8: 0.773 | H8: 2276 | I8: 0.559 | J8: 2954 | K8: 0.653
A9: 6 | B9: Collision_06_Catapult | C9: 1.2 | D9: 612 | E9: 0.21 | F9: 579 | G9: 0.167 | H9: 747 | I9: 0.165 | J9: 602 | K9: 0.208
A10: 7 | B10: Collision_07_Ball_Finite_Plane_Float | C10: 1.5 | D10: 210 | E10: 0.079 | F10: 213 | G10: 0.045 | H10: 221 | I10: 0.056 | J10: 223 | K10: 0.047
A11: 8 | B11: Collision_08_Compare_Forces | C11: 5 | D11: 9225 | E11: 5.325 | F11: 17963 | G11: 6.908 | H11: 10816 | I11: 3.797 | J11: 21376 | K11: 10.728
A12: 9 | B12: Friction_01_Box_on_Ramp_Constraint | C12: 10 | D12: 1137 | E12: 0.165 | F12: 1137 | G12: 0.101 | H12: 1137 | I12: 0.091 | J12: 1137 | K12: 0.101
A13: 10 | B13: Friction_02_Box_on_Ramp | C13: 10 | D13: 1312 | E13: 0.187 | F13: 1420 | G13: 0.22 | H13: 1398 | I13: 0.169 | J13: 1544 | K13: 0.242
A14: 11 | B14: Friction_03_Double_Pendulum_Constraint | C14: 45 | D14: 5530 | E14: 1.043 | F14: 5530 | G14: 0.717 | H14: 5530 | I14: 0.599 | J14: 5530 | K14: 0.545
A15: 12 | B15: Friction_04_Disk_Rolling_on_Ramp | C15: 4 | D15: 721 | E15: 0.144 | F15: 860 | G15: 0.122 | H15: 800 | I15: 0.113 | J15: 989 | K15: 0.152
... A47: 44 | B47: sm_tread_drive | C47: 50 | D47: 5535 | E47: 4.425 | F47: 9437 | G47: 6.429 | H47: 5565 | I47: 3.258 | J47: 9610 | K47: 7.044
A48: 45 | B48: Mini Golf Hole 1 | C48: 33.72 | D48: 9375 | E48: 5.683 | F48: n/a | G48: n/a | H48: n/a | I48: n/a | J48: n/a | K48: n/a
A49: 46 | B49: Mini Golf Hole 2 | C49: 32.19 | D49: 8828 | E49: 5.443 | F49: n/a | G49: n/a | H49: n/a | I49: n/a | J49: n/a | K49: n/a
A50: 47 | B50: Mini Golf Hole 3 | C50: 59.18 | D50: 15140 | E50: 9.631 | F50: n/a | G50: n/a | H50: n/a | I50: n/a | J50: n/a | K50: n/a
A51: 48 | B51: Mini Golf Hole 4 | C51: 39.02 | D51: 11499 | E51: 7.591 | F51: n/a | G51: n/a | H51: n/a | I51: n/a | J51: n/a | K51: n/a
A52: 49 | B52: Mini Golf Hole 5 | C52: 34.68 | D52: 9443 | E52: 4.849 | F52: n/a | G52: n/a | H52: n/a | I52: n/a | J52: n/a | K52: n/a
A53: 50 | B53: Mini Golf Hole 6 | C53: 40.82 | D53: 11825 | E53: 10.99 | F53: n/a | G53: n/a | H53: n/a | I53: n/a | J53: n/a | K53: n/a
A54: 51 | B54: Mini Golf Hole 7 | C54: 41.28 | D54: 11517 | E54: 8.374 | F54: n/a | G54: n/a | H54: n/a | I54: n/a | J54: n/a | K54: n/a
A55: 52 | B55: Mini Golf Hole 8 | C55: 45.27 | D55: 12245 | E55: 13.752 | F55: n/a | G55: n/a | H55: n/a | I55: n/a | J55: n/a | K55: n/a
A56: 53 | B56: Mini Golf Hole 9 | C56: 27.71 | D56: 8945 | E56: 8.993 | F56: n/a | G56: n/a | H56: n/a | I56: n/a | J56: n/a | K56: n/a

Sheet Delta17a
B1: Contact Forces Tests | C1: R17a-R16b | H1: CFL v3.6
D2: Linear, No Friction | F2: Linear, Stick-Slip C | H2: Nonlin., No Friction | J2: Nonlin., Stick-Slip C
A3: # | B3: Model | C3: Stop Time | D3: # Steps | E3: Sim Time | F3: # Steps | G3: Sim Time | H3: # Steps | I3: Sim Time | J3: # Steps | K3: Sim Time
A4: 1 | B4: Collision_01_Ball_Infinite_Plane | C4: 20 | D4: =('R16b_v3p6'!D4-'R17a_v3p6'!D4)/'R16b_v3p6'!D4 -> 0 | E4: =('R16b_v3p6'!E4-'R17a_v3p6'!E4)/'R16b_v3p6'!E4 -> 0.76027107 | F4: =('R16b_v3p6'!F4-'R17a_v3p6'!F4)/'R16b_v3p6'!F4 -> 0 | G4: =('R16b_v3p6'!G4-'R17a_v3p6'!G4)/'R16b_v3p6'!G4 -> -0.014778325 | H4: =('R16b_v3p6'!H4-'R17a_v3p6'!H4)/'R16b_v3p6'!H4 -> 0 | I4: =('R16b_v3p6'!I4-'R17a_v3p6'!I4)/'R16b_v3p6'!I4 -> -0.17948718 | J4: =('R16b_v3p6'!J4-'R17a_v3p6'!J4)/'R16b_v3p6'!J4 -> 0 | K4: =('R16b_v3p6'!K4-'R17a_v3p6'!K4)/'R16b_v3p6'!K4 -> 0.032967033
A5: 2 | B5: Collision_02_Disk_Finite_Plane_Fixed | C5: 4 | D5: =('R16b_v3p6'!D5-'R17a_v3p6'!D5)/'R16b_v3p6'!D5 -> 0 | E5: =('R16b_v3p6'!E5-'R17a_v3p6'!E5)/'R16b_v3p6'!E5 -> -1.6731235 | F5: =('R16b_v3p6'!F5-'R17a_v3p6'!F5)/'R16b_v3p6'!F5 -> 0 | G5: =('R16b_v3p6'!G5-'R17a_v3p6'!G5)/'R16b_v3p6'!G5 -> -0.57317073 | H5: =('R16b_v3p6'!H5-'R17a_v3p6'!H5)/'R16b_v3p6'!H5 -> 0 | I5: =('R16b_v3p6'!I5-'R17a_v3p6'!I5)/'R16b_v3p6'!I5 -> -0.73913043 | J5: =('R16b_v3p6'!J5-'R17a_v3p6'!J5)/'R16b_v3p6'!J5 -> 0 | K5: =('R16b_v3p6'!K5-'R17a_v3p6'!K5)/'R16b_v3p6'!K5 -> -0.31914894
A6: 3 | B6: Collision_03_Disk_Finite_Plane_Spin | C6: 1.5 | D6: =('R16b_v3p6'!D6-'R17a_v3p6'!D6)/'R16b_v3p6'!D6 -> 0 | E6: =('R16b_v3p6'!E6-'R17a_v3p6'!E6)/'R16b_v3p6'!E6 -> -0.7483871 | F6: =('R16b_v3p6'!F6-'R17a_v3p6'!F6)/'R16b_v3p6'!F6 -> 0 | G6: =('R16b_v3p6'!G6-'R17a_v3p6'!G6)/'R16b_v3p6'!G6 -> -0.34920635 | H6: =('R16b_v3p6'!H6-'R17a_v3p6'!H6)/'R16b_v3p6'!H6 -> 0 | I6: =('R16b_v3p6'!I6-'R17a_v3p6'!I6)/'R16b_v3p6'!I6 -> -0.61538462 | J6: =('R16b_v3p6'!J6-'R17a_v3p6'!J6)/'R16b_v3p6'!J6 -> 0 | K6: =('R16b_v3p6'!K6-'R17a_v3p6'!K6)/'R16b_v3p6'!K6 -> -0.29310345
A7: 4 | B7: Collision_04_Disks_in_Box | C7: 3 | D7: =('R16b_v3p6'!D7-'R17a_v3p6'!D7)/'R16b_v3p6'!D7 -> 0 | E7: =('R16b_v3p6'!E7-'R17a_v3p6'!E7)/'R16b_v3p6'!E7 -> -0.011546185 | F7: =('R16b_v3p6'!F7-'R17a_v3p6'!F7)/'R16b_v3p6'!F7 -> 0 | G7: =('R16b_v3p6'!G7-'R17a_v3p6'!G7)/'R16b_v3p6'!G7 -> -0.067810799 | H7: =('R16b_v3p6'!H7-'R17a_v3p6'!H7)/'R16b_v3p6'!H7 -> 0 | I7: =('R16b_v3p6'!I7-'R17a_v3p6'!I7)/'R16b_v3p6'!I7 -> 0.068565401 | J7: =('R16b_v3p6'!J7-'R17a_v3p6'!J7)/'R16b_v3p6'!J7 -> 0 | K7: =('R16b_v3p6'!K7-'R17a_v3p6'!K7)/'R16b_v3p6'!K7 -> 0.0026518804
A8: 5 | B8: Collision_05_Disk_in_Ring | C8: 5 | D8: =('R16b_v3p6'!D8-'R17a_v3p6'!D8)/'R16b_v3p6'!D8 -> 0 | E8: =('R16b_v3p6'!E8-'R17a_v3p6'!E8)/'R16b_v3p6'!E8 -> -0.6981982 | F8: =('R16b_v3p6'!F8-'R17a_v3p6'!F8)/'R16b_v3p6'!F8 -> 0 | G8: =('R16b_v3p6'!G8-'R17a_v3p6'!G8)/'R16b_v3p6'!G8 -> -0.42307692 | H8: =('R16b_v3p6'!H8-'R17a_v3p6'!H8)/'R16b_v3p6'!H8 -> 0 | I8: =('R16b_v3p6'!I8-'R17a_v3p6'!I8)/'R16b_v3p6'!I8 -> -0.80612245 | J8: =('R16b_v3p6'!J8-'R17a_v3p6'!J8)/'R16b_v3p6'!J8 -> 0 | K8: =('R16b_v3p6'!K8-'R17a_v3p6'!K8)/'R16b_v3p6'!K8 -> -0.48220065
A9: 6 | B9: Collision_06_Catapult | C9: 1.2 | D9: =('R16b_v3p6'!D9-'R17a_v3p6'!D9)/'R16b_v3p6'!D9 -> 0 | E9: =('R16b_v3p6'!E9-'R17a_v3p6'!E9)/'R16b_v3p6'!E9 -> -0.25 | F9: =('R16b_v3p6'!F9-'R17a_v3p6'!F9)/'R16b_v3p6'!F9 -> 0 | G9: =('R16b_v3p6'!G9-'R17a_v3p6'!G9)/'R16b_v3p6'!G9 -> 0 | H9: =('R16b_v3p6'!H9-'R17a_v3p6'!H9)/'R16b_v3p6'!H9 -> 0 | I9: =('R16b_v3p6'!I9-'R17a_v3p6'!I9)/'R16b_v3p6'!I9 -> -0.2195122 | J9: =('R16b_v3p6'!J9-'R17a_v3p6'!J9)/'R16b_v3p6'!J9 -> 0 | K9: =('R16b_v3p6'!K9-'R17a_v3p6'!K9)/'R16b_v3p6'!K9 -> -0.14173228
A10: 7 | B10: Collision_07_Ball_Finite_Plane_Float | C10: 1.5 | D10: =('R16b_v3p6'!D10-'R17a_v3p6'!D10)/'R16b_v3p6'!D10 -> 0 | E10: =('R16b_v3p6'!E10-'R17a_v3p6'!E10)/'R16b_v3p6'!E10 -> -0.18 | F10: =('R16b_v3p6'!F10-'R17a_v3p6'!F10)/'R16b_v3p6'!F10 -> 0 | G10: =('R16b_v3p6'!G10-'R17a_v3p6'!G10)/'R16b_v3p6'!G10 -> -0.33333333 | H10: =('R16b_v3p6'!H10-'R17a_v3p6'!H10)/'R16b_v3p6'!H10 -> 0 | I10: =('R16b_v3p6'!I10-'R17a_v3p6'!I10)/'R16b_v3p6'!I10 -> -0.42857143 | J10: =('R16b_v3p6'!J10-'R17a_v3p6'!J10)/'R16b_v3p6'!J10 -> 0 | K10: =('R16b_v3p6'!K10-'R17a_v3p6'!K10)/'R16b_v3p6'!K10 -> -0.33333333
A11: 8 | B11: Collision_08_Compare_Forces | C11: 5 | D11: =('R16b_v3p6'!D11-'R17a_v3p6'!D11)/'R16b_v3p6'!D11 -> 0 | E11: =('R16b_v3p6'!E11-'R17a_v3p6'!E11)/'R16b_v3p6'!E11 -> 0.056324111 | F11: =('R16b_v3p6'!F11-'R17a_v3p6'!F11)/'R16b_v3p6'!F11 -> 0 | G11: =('R16b_v3p6'!G11-'R17a_v3p6'!G11)/'R16b_v3p6'!G11 -> 0.061170947 | H11: =('R16b_v3p6'!H11-'R17a_v3p6'!H11)/'R16b_v3p6'!H11 -> 0 | I11: =('R16b_v3p6'!I11-'R17a_v3p6'!I11)/'R16b_v3p6'!I11 -> 0.12360669 | J11: =('R16b_v3p6'!J11-'R17a_v3p6'!J11)/'R16b_v3p6'!J11 -> 0 | K11: =('R16b_v3p6'!K11-'R17a_v3p6'!K11)/'R16b_v3p6'!K11 -> -0.036763771
A12: 9 | B12: Friction_01_Box_on_Ramp_Constraint | C12: 10 | D12: =('R16b_v3p6'!D12-'R17a_v3p6'!D12)/'R16b_v3p6'!D12 -> 0 | E12: =('R16b_v3p6'!E12-'R17a_v3p6'!E12)/'R16b_v3p6'!E12 -> -0.13375796 | F12: =('R16b_v3p6'!F12-'R17a_v3p6'!F12)/'R16b_v3p6'!F12 -> 0 | G12: =('R16b_v3p6'!G12-'R17a_v3p6'!G12)/'R16b_v3p6'!G12 -> -0.022222222 | H12: =('R16b_v3p6'!H12-'R17a_v3p6'!H12)/'R16b_v3p6'!H12 -> 0 | I12: =('R16b_v3p6'!I12-'R17a_v3p6'!I12)/'R16b_v3p6'!I12 -> -0.069767442 | J12: =('R16b_v3p6'!J12-'R17a_v3p6'!J12)/'R16b_v3p6'!J12 -> 0 | K12: =('R16b_v3p6'!K12-'R17a_v3p6'!K12)/'R16b_v3p6'!K12 -> -0.033707865
A13: 10 | B13: Friction_02_Box_on_Ramp | C13: 10 | D13: =('R16b_v3p6'!D13-'R17a_v3p6'!D13)/'R16b_v3p6'!D13 -> 0 | E13: =('R16b_v3p6'!E13-'R17a_v3p6'!E13)/'R16b_v3p6'!E13 -> -0.1257485 | F13: =('R16b_v3p6'!F13-'R17a_v3p6'!F13)/'R16b_v3p6'!F13 -> 0 | G13: =('R16b_v3p6'!G13-'R17a_v3p6'!G13)/'R16b_v3p6'!G13 -> 0.065989848 | H13: =('R16b_v3p6'!H13-'R17a_v3p6'!H13)/'R16b_v3p6'!H13 -> 0 | I13: =('R16b_v3p6'!I13-'R17a_v3p6'!I13)/'R16b_v3p6'!I13 -> 0.15642458 | J13: =('R16b_v3p6'!J13-'R17a_v3p6'!J13)/'R16b_v3p6'!J13 -> 0 | K13: =('R16b_v3p6'!K13-'R17a_v3p6'!K13)/'R16b_v3p6'!K13 -> -0.015463918
A14: 11 | B14: Friction_03_Double_Pendulum_Constraint | C14: 45 | D14: =('R16b_v3p6'!D14-'R17a_v3p6'!D14)/'R16b_v3p6'!D14 -> 0 | E14: =('R16b_v3p6'!E14-'R17a_v3p6'!E14)/'R16b_v3p6'!E14 -> -0.2425 | F14: =('R16b_v3p6'!F14-'R17a_v3p6'!F14)/'R16b_v3p6'!F14 -> 0 | G14: =('R16b_v3p6'!G14-'R17a_v3p6'!G14)/'R16b_v3p6'!G14 -> -0.47058824 | H14: =('R16b_v3p6'!H14-'R17a_v3p6'!H14)/'R16b_v3p6'!H14 -> 0 | I14: =('R16b_v3p6'!I14-'R17a_v3p6'!I14)/'R16b_v3p6'!I14 -> -0.62934363 | J14: =('R16b_v3p6'!J14-'R17a_v3p6'!J14)/'R16b_v3p6'!J14 -> 0 | K14: =('R16b_v3p6'!K14-'R17a_v3p6'!K14)/'R16b_v3p6'!K14 -> -0.65461847
A15: 12 | B15: Friction_04_Disk_Rolling_on_Ramp | C15: 4 | D15: =('R16b_v3p6'!D15-'R17a_v3p6'!D15)/'R16b_v3p6'!D15 -> 0 | E15: =('R16b_v3p6'!E15-'R17a_v3p6'!E15)/'R16b_v3p6'!E15 -> -0.038461538 | F15: =('R16b_v3p6'!F15-'R17a_v3p6'!F15)/'R16b_v3p6'!F15 -> 0 | G15: =('R16b_v3p6'!G15-'R17a_v3p6'!G15)/'R16b_v3p6'!G15 -> -0.14473684 | H15: =('R16b_v3p6'!H15-'R17a_v3p6'!H15)/'R16b_v3p6'!H15 -> 0 | I15: =('R16b_v3p6'!I15-'R17a_v3p6'!I15)/'R16b_v3p6'!I15 -> -0.20588235 | J15: =('R16b_v3p6'!J15-'R17a_v3p6'!J15)/'R16b_v3p6'!J15 -> 0 | K15: =('R16b_v3p6'!K15-'R17a_v3p6'!K15)/'R16b_v3p6'!K15 -> -0.13636364
... A38: 35 | B38: Robot_2_Whl | C38: 24 | D38: =('R16b_v3p6'!D38-'R17a_v3p6'!D38)/'R16b_v3p6'!D38 -> 0 | E38: =('R16b_v3p6'!E38-'R17a_v3p6'!E38)/'R16b_v3p6'!E38 -> 0.14317673 | F38: =('R16b_v3p6'!F38-'R17a_v3p6'!F38)/'R16b_v3p6'!F38 -> 0 | G38: =('R16b_v3p6'!G38-'R17a_v3p6'!G38)/'R16b_v3p6'!G38 -> -0.15868263 | H38: =('R16b_v3p6'!H38-'R17a_v3p6'!H38)/'R16b_v3p6'!H38 -> 0 | I38: =('R16b_v3p6'!I38-'R17a_v3p6'!I38)/'R16b_v3p6'!I38 -> -0.037926675 | J38: =('R16b_v3p6'!J38-'R17a_v3p6'!J38)/'R16b_v3p6'!J38 -> 0 | K38: =('R16b_v3p6'!K38-'R17a_v3p6'!K38)/'R16b_v3p6'!K38 -> -0.042492918
A39: 36 | B39: Mini Golf Hole 1 | C39: 33.72 | D39: =('R16b_v3p6'!D39-'R17a_v3p6'!D39)/'R16b_v3p6'!D39 -> 0 | E39: =('R16b_v3p6'!E39-'R17a_v3p6'!E39)/'R16b_v3p6'!E39 -> -0.2244586 | F39: n/a | G39: n/a | H39: n/a | I39: n/a | J39: n/a | K39: n/a
A40: 37 | B40: Mini Golf Hole 2 | C40: 32.19 | D40: =('R16b_v3p6'!D40-'R17a_v3p6'!D40)/'R16b_v3p6'!D40 -> 0 | E40: =('R16b_v3p6'!E40-'R17a_v3p6'!E40)/'R16b_v3p6'!E40 -> -0.015752033 | F40: n/a | G40: n/a | H40: n/a | I40: n/a | J40: n/a | K40: n/a
A41: 38 | B41: Mini Golf Hole 3 | C41: 59.19 | D41: =('R16b_v3p6'!D41-'R17a_v3p6'!D41)/'R16b_v3p6'!D41 -> 0 | E41: =('R16b_v3p6'!E41-'R17a_v3p6'!E41)/'R16b_v3p6'!E41 -> 0.06116548 | F41: n/a | G41: n/a | H41: n/a | I41: n/a | J41: n/a | K41: n/a
A42: 39 | B42: Mini Golf Hole 4 | C42: 39.01 | D42: =('R16b_v3p6'!D42-'R17a_v3p6'!D42)/'R16b_v3p6'!D42 -> 0 | E42: =('R16b_v3p6'!E42-'R17a_v3p6'!E42)/'R16b_v3p6'!E42 -> 0.060215467 | F42: n/a | G42: n/a | H42: n/a | I42: n/a | J42: n/a | K42: n/a
A43: 40 | B43: Mini Golf Hole 5 | C43: 34.64 | D43: =('R16b_v3p6'!D43-'R17a_v3p6'!D43)/'R16b_v3p6'!D43 -> 0 | E43: =('R16b_v3p6'!E43-'R17a_v3p6'!E43)/'R16b_v3p6'!E43 -> -0.042454728 | F43: n/a | G43: n/a | H43: n/a | I43: n/a | J43: n/a | K43: n/a
A44: 41 | B44: Mini Golf Hole 6 | C44: 40.98 | D44: =('R16b_v3p6'!D44-'R17a_v3p6'!D44)/'R16b_v3p6'!D44 -> 0 | E44: =('R16b_v3p6'!E44-'R17a_v3p6'!E44)/'R16b_v3p6'!E44 -> 0.072856147 | F44: n/a | G44: n/a | H44: n/a | I44: n/a | J44: n/a | K44: n/a
A45: 42 | B45: Mini Golf Hole 7 | C45: 41.28 | D45: =('R16b_v3p6'!D45-'R17a_v3p6'!D45)/'R16b_v3p6'!D45 -> 0 | E45: =('R16b_v3p6'!E45-'R17a_v3p6'!E45)/'R16b_v3p6'!E45 -> 0.045713202 | F45: n/a | G45: n/a | H45: n/a | I45: n/a | J45: n/a | K45: n/a
A46: 43 | B46: Mini Golf Hole 8 | C46: 45.28 | D46: =('R16b_v3p6'!D46-'R17a_v3p6'!D46)/'R16b_v3p6'!D46 -> 0 | E46: =('R16b_v3p6'!E46-'R17a_v3p6'!E46)/'R16b_v3p6'!E46 -> 0.11159475 | F46: n/a | G46: n/a | H46: n/a | I46: n/a | J46: n/a | K46: n/a
A47: 44 | B47: Mini Golf Hole 9 | C47: 27.71 | D47: =('R16b_v3p6'!D47-'R17a_v3p6'!D47)/'R16b_v3p6'!D47 -> 0 | E47: =('R16b_v3p6'!E47-'R17a_v3p6'!E47)/'R16b_v3p6'!E47 -> 0.017120075 | F47: n/a | G47: n/a | H47: n/a | I47: n/a | J47: n/a | K47: n/a

Sheet R19b_bash_5p0
B1: Contact Forces Tests | C1: 9.7.0.1141441 (R2019b) Prerelease Update 2 | F1: 43658.785 | H1: CFL v5.0
D2: Linear, No Friction | F2: Linear, Stick-Slip C | H2: Nonlin., No Friction | J2: Nonlin., Stick-Slip C
A3: # | B3: Model | C3: Stop Time | D3: # Steps | E3: Sim Time | F3: # Steps | G3: Sim Time | H3: # Steps | I3: Sim Time | J3: # Steps | K3: Sim Time
A4: 1 | B4: Collision_01_Ball_Infinite_Plane | C4: 6 | D4: 2388 | E4: 0.842 | F4: 2388 | G4: 0.481 | H4: 2388 | I4: 0.611 | J4: 2388 | K4: 0.629
A5: 2 | B5: Collision_02_Disk_Finite_Plane_Fixed | C5: 4 | D5: 669 | E5: 0.267 | F5: 935 | G5: 0.329 | H5: 718 | I5: 0.83 | J5: 1020 | K5: 0.214
A6: 3 | B6: Collision_03_Disk_Finite_Plane_Spin | C6: 1.5 | D6: 298 | E6: 0.23 | F6: 370 | G6: 0.103 | H6: 317 | I6: 0.141 | J6: 398 | K6: 0.105
A7: 4 | B7: Collision_04_Disks_in_Box | C7: 3 | D7: 3726 | E7: 3.837 | F7: 4928 | G7: 3.434 | H7: 5039 | I7: 2.965 | J7: 6295 | K7: 4.523
A8: 5 | B8: Collision_05_Disk_in_Ring | C8: 5 | D8: 2071 | E8: 0.687 | F8: 2660 | G8: 0.538 | H8: 2276 | I8: 0.493 | J8: 2954 | K8: 0.854
A9: 6 | B9: Collision_06_Catapult | C9: 1.2 | D9: 612 | E9: 0.269 | F9: 579 | G9: 0.224 | H9: 747 | I9: 0.312 | J9: 602 | K9: 0.247
A10: 7 | B10: Collision_07_Ball_Finite_Plane_Float | C10: 1.5 | D10: 210 | E10: 0.105 | F10: 213 | G10: 0.071 | H10: 221 | I10: 0.091 | J10: 223 | K10: 0.069
A11: 8 | B11: Collision_08_Compare_Forces | C11: 5 | D11: 9225 | E11: 4.462 | F11: 17963 | G11: 7.662 | H11: 10816 | I11: 4.085 | J11: 21376 | K11: 8.185
A12: 9 | B12: Friction_01_Box_on_Ramp_Constraint | C12: 10 | D12: 1137 | E12: 0.209 | F12: 1137 | G12: 0.162 | H12: 1137 | I12: 0.17 | J12: 1137 | K12: 0.137
A13: 10 | B13: Friction_02_Box_on_Ramp | C13: 10 | D13: 1312 | E13: 0.603 | F13: 1420 | G13: 0.504 | H13: 1398 | I13: 0.424 | J13: 1544 | K13: 0.6
A14: 11 | B14: Friction_03_Double_Pendulum_Constraint | C14: 45 | D14: 5530 | E14: 0.617 | F14: 5530 | G14: 0.746 | H14: 5530 | I14: 0.53 | J14: 5530 | K14: 0.726
A15: 12 | B15: Friction_04_Disk_Rolling_on_Ramp | C15: 4 | D15: 721 | E15: 0.207 | F15: 860 | G15: 0.145 | H15: 800 | I15: 0.152 | J15: 989 | K15: 0.182
... A47: 44 | B47: sm_tread_drive | C47: 50 | D47: 5535 | E47: 8.462 | F47: 9437 | G47: 12.635 | H47: 5565 | I47: 6.402 | J47: 9610 | K47: 13.441
A48: 45 | B48: Mini Golf Hole 1 | C48: 33.72 | D48: 9375 | E48: 8.597 | F48: n/a | G48: n/a | H48: n/a | I48: n/a | J48: n/a | K48: n/a
A49: 46 | B49: Mini Golf Hole 2 | C49: 32.19 | D49: 8828 | E49: 7.761 | F49: n/a | G49: n/a | H49: n/a | I49: n/a | J49: n/a | K49: n/a
A50: 47 | B50: Mini Golf Hole 3 | C50: 59.18 | D50: 15140 | E50: 14.716 | F50: n/a | G50: n/a | H50: n/a | I50: n/a | J50: n/a | K50: n/a
A51: 48 | B51: Mini Golf Hole 4 | C51: 39.02 | D51: 11499 | E51: 12.787 | F51: n/a | G51: n/a | H51: n/a | I51: n/a | J51: n/a | K51: n/a
A52: 49 | B52: Mini Golf Hole 5 | C52: 34.68 | D52: 9443 | E52: 14.028 | F52: n/a | G52: n/a | H52: n/a | I52: n/a | J52: n/a | K52: n/a
A53: 50 | B53: Mini Golf Hole 6 | C53: 40.82 | D53: 11825 | E53: 18.849 | F53: n/a | G53: n/a | H53: n/a | I53: n/a | J53: n/a | K53: n/a
A54: 51 | B54: Mini Golf Hole 7 | C54: 41.28 | D54: 11517 | E54: 17.192 | F54: n/a | G54: n/a | H54: n/a | I54: n/a | J54: n/a | K54: n/a
A55: 52 | B55: Mini Golf Hole 8 | C55: 45.27 | D55: 12245 | E55: 26.199 | F55: n/a | G55: n/a | H55: n/a | I55: n/a | J55: n/a | K55: n/a
A56: 53 | B56: Mini Golf Hole 9 | C56: 27.71 | D56: 8945 | E56: 20.496 | F56: n/a | G56: n/a | H56: n/a | I56: n/a | J56: n/a | K56: n/a

Sheet R20a_5p0
B1: Contact Forces Tests | C1: 9.8.0.1323502 (R2020a) | F1: 11-Mar-2020 00:38:31 | H1: CFL v5.0
D2: Linear, No Friction | F2: Linear, Stick-Slip C | H2: Nonlin., No Friction | J2: Nonlin., Stick-Slip C
A3: # | B3: Model | C3: Stop Time | D3: # Steps | E3: Sim Time | F3: # Steps | G3: Sim Time | H3: # Steps | I3: Sim Time | J3: # Steps | K3: Sim Time
A4: 1 | B4: Collision_01_Ball_Infinite_Plane | C4: 6 | D4: 2401 | E4: 0.677 | F4: 2401 | G4: 0.472 | H4: 2401 | I4: 0.418 | J4: 2401 | K4: 0.426
A5: 2 | B5: Collision_02_Disk_Finite_Plane_Fixed | C5: 4 | D5: 669 | E5: 0.32 | F5: 935 | G5: 0.153 | H5: 718 | I5: 0.14 | J5: 1008 | K5: 0.146
A6: 3 | B6: Collision_03_Disk_Finite_Plane_Spin | C6: 1.5 | D6: 298 | E6: 0.384 | F6: 366 | G6: 0.09 | H6: 317 | I6: 0.089 | J6: 397 | K6: 0.096
A7: 4 | B7: Collision_04_Disks_in_Box | C7: 3 | D7: 3765 | E7: 2.525 | F7: 4749 | G7: 3.559 | H7: 5071 | I7: 3.307 | J7: 6035 | K7: 4.443
A8: 5 | B8: Collision_05_Disk_in_Ring | C8: 5 | D8: 2052 | E8: 0.697 | F8: 2629 | G8: 0.773 | H8: 2285 | I8: 0.423 | J8: 2985 | K8: 0.652
A9: 6 | B9: Collision_06_Catapult | C9: 1.2 | D9: 620 | E9: 0.285 | F9: 585 | G9: 0.166 | H9: 747 | I9: 0.182 | J9: 487 | K9: 0.142
A10: 7 | B10: Collision_07_Ball_Finite_Plane_Float | C10: 1.5 | D10: 210 | E10: 0.116 | F10: 213 | G10: 0.065 | H10: 222 | I10: 0.06 | J10: 225 | K10: 0.065
A11: 8 | B11: Collision_08_Compare_Forces | C11: 5 | D11: 9335 | E11: 4.322 | F11: 18756 | G11: 6.719 | H11: 11535 | I11: 5.241 | J11: 20609 | K11: 7.997
A12: 9 | B12: Friction_01_Box_on_Ramp_Constraint | C12: 10 | D12: 1137 | E12: 0.255 | F12: 1137 | G12: 0.092 | H12: 1137 | I12: 0.089 | J12: 1137 | K12: 0.09
A13: 10 | B13: Friction_02_Box_on_Ramp | C13: 10 | D13: 1313 | E13: 0.66 | F13: 1401 | G13: 0.616 | H13: 1398 | I13: 0.386 | J13: 1490 | K13: 0.538
A14: 11 | B14: Friction_03_Double_Pendulum_Constraint | C14: 45 | D14: 5512 | E14: 0.866 | F14: 5512 | G14: 0.803 | H14: 5512 | I14: 0.456 | J14: 5512 | K14: 0.548
A15: 12 | B15: Friction_04_Disk_Rolling_on_Ramp | C15: 4 | D15: 721 | E15: 0.238 | F15: 858 | G15: 0.175 | H15: 779 | I15: 0.155 | J15: 943 | K15: 0.132
... A47: 44 | B47: sm_tread_drive | C47: 50 | D47: 5545 | E47: 5.998 | F47: 9367 | G47: 19.021 | H47: 5581 | I47: 7.6 | J47: 9597 | K47: 13.762
A48: 45 | B48: Mini Golf Hole 1 | C48: 33.72 | D48: 8619 | E48: 7.899 | F48: n/a | G48: n/a | H48: n/a | I48: n/a | J48: n/a | K48: n/a
A49: 46 | B49: Mini Golf Hole 2 | C49: 32.19 | D49: 8159 | E49: 7.272 | F49: n/a | G49: n/a | H49: n/a | I49: n/a | J49: n/a | K49: n/a
A50: 47 | B50: Mini Golf Hole 3 | C50: 59.18 | D50: 15122 | E50: 172.877 | F50: n/a | G50: n/a | H50: n/a | I50: n/a | J50: n/a | K50: n/a
A51: 48 | B51: Mini Golf Hole 4 | C51: 39.01 | D51: 11715 | E51: 10.912 | F51: n/a | G51: n/a | H51: n/a | I51: n/a | J51: n/a | K51: n/a
A52: 49 | B52: Mini Golf Hole 5 | C52: 34.67 | D52: 9536 | E52: 9.015 | F52: n/a | G52: n/a | H52: n/a | I52: n/a | J52: n/a | K52: n/a
A53: 50 | B53: Mini Golf Hole 6 | C53: 40.86 | D53: 11894 | E53: 19.131 | F53: n/a | G53: n/a | H53: n/a | I53: n/a | J53: n/a | K53: n/a
A54: 51 | B54: Mini Golf Hole 7 | C54: 41.27 | D54: 11457 | E54: 11.077 | F54: n/a | G54: n/a | H54: n/a | I54: n/a | J54: n/a | K54: n/a
A55: 52 | B55: Mini Golf Hole 8 | C55: 45.28 | D55: 12110 | E55: 22.964 | F55: n/a | G55: n/a | H55: n/a | I55: n/a | J55: n/a | K55: n/a
A56: 53 | B56: Mini Golf Hole 9 | C56: 27.71 | D56: 8892 | E56: 12.916 | F56: n/a | G56: n/a | H56: n/a | I56: n/a | J56: n/a | K56: n/a

Sheet R20b_5p0
B1: Contact Forces Tests | C1: 9.9.0.1467703 (R2020b) | F1: 44094.796 | H1: CFL v5.0
D2: Linear, No Friction | F2: Linear, Stick-Slip C | H2: Nonlin., No Friction | J2: Nonlin., Stick-Slip C
A3: # | B3: Model | C3: Stop Time | D3: # Steps | E3: Sim Time | F3: # Steps | G3: Sim Time | H3: # Steps | I3: Sim Time | J3: # Steps | K3: Sim Time
A4: 1 | B4: Collision_01_Ball_Infinite_Plane | C4: 6 | D4: 2401 | E4: 0.931 | F4: 2401 | G4: 0.471 | H4: 2401 | I4: 0.435 | J4: 2401 | K4: 0.426
A5: 2 | B5: Collision_02_Disk_Finite_Plane_Fixed | C5: 4 | D5: 669 | E5: 0.836 | F5: 935 | G5: 0.183 | H5: 718 | I5: 0.124 | J5: 1008 | K5: 0.169
A6: 3 | B6: Collision_03_Disk_Finite_Plane_Spin | C6: 1.5 | D6: 298 | E6: 0.273 | F6: 366 | G6: 0.093 | H6: 317 | I6: 0.068 | J6: 400 | K6: 0.075
A7: 4 | B7: Collision_04_Disks_in_Box | C7: 3 | D7: 3765 | E7: 3.381 | F7: 4749 | G7: 4.23 | H7: 5071 | I7: 4.557 | J7: 6035 | K7: 5.771
A8: 5 | B8: Collision_05_Disk_in_Ring | C8: 5 | D8: 2052 | E8: 0.672 | F8: 2639 | G8: 0.788 | H8: 2285 | I8: 0.511 | J8: 2949 | K8: 0.693
A9: 6 | B9: Collision_06_Catapult | C9: 1.2 | D9: 604 | E9: 0.328 | F9: 582 | G9: 0.186 | H9: 665 | I9: 0.211 | J9: 484 | K9: 0.165
A10: 7 | B10: Collision_07_Ball_Finite_Plane_Float | C10: 1.5 | D10: 210 | E10: 0.193 | F10: 213 | G10: 0.079 | H10: 222 | I10: 0.071 | J10: 225 | K10: 0.074
A11: 8 | B11: Collision_08_Compare_Forces | C11: 5 | D11: 9430 | E11: 3.772 | F11: 18796 | G11: 8.431 | H11: 11385 | I11: 5.065 | J11: 20520 | K11: 10.176
A12: 9 | B12: Friction_01_Box_on_Ramp_Constraint | C12: 10 | D12: 1137 | E12: 0.22 | F12: 1137 | G12: 0.173 | H12: 1137 | I12: 0.135 | J12: 1137 | K12: 0.119
A13: 10 | B13: Friction_02_Box_on_Ramp | C13: 10 | D13: 1313 | E13: 0.749 | F13: 1401 | G13: 0.799 | H13: 1398 | I13: 0.494 | J13: 1490 | K13: 0.605
A14: 11 | B14: Friction_03_Double_Pendulum_Constraint | C14: 45 | D14: 5535 | E14: 1.063 | F14: 5535 | G14: 1.028 | H14: 5535 | I14: 0.867 | J14: 5535 | K14: 0.759
A15: 12 | B15: Friction_04_Disk_Rolling_on_Ramp | C15: 4 | D15: 721 | E15: 0.238 | F15: 858 | G15: 0.156 | H15: 779 | I15: 0.153 | J15: 943 | K15: 0.152
... A47: 44 | B47: sm_tread_drive | C47: 50 | D47: 5541 | E47: 5.79 | F47: 9380 | G47: 10.028 | H47: 5581 | I47: 5.477 | J47: 9597 | K47: 12.907
A48: 45 | B48: Mini Golf Hole 1 | C48: 33.72 | D48: 8619 | E48: 7.603 | F48: n/a | G48: n/a | H48: n/a | I48: n/a | J48: n/a | K48: n/a
A49: 46 | B49: Mini Golf Hole 2 | C49: 32.19 | D49: 8159 | E49: 7.049 | F49: n/a | G49: n/a | H49: n/a | I49: n/a | J49: n/a | K49: n/a
A50: 47 | B50: Mini Golf Hole 3 | C50: 59.18 | D50: 15122 | E50: 20.718 | F50: n/a | G50: n/a | H50: n/a | I50: n/a | J50: n/a | K50: n/a
A51: 48 | B51: Mini Golf Hole 4 | C51: 39.01 | D51: 11715 | E51: 11.837 | F51: n/a | G51: n/a | H51: n/a | I51: n/a | J51: n/a | K51: n/a
A52: 49 | B52: Mini Golf Hole 5 | C52: 34.67 | D52: 9536 | E52: 9.926 | F52: n/a | G52: n/a | H52: n/a | I52: n/a | J52: n/a | K52: n/a
A53: 50 | B53: Mini Golf Hole 6 | C53: 40.86 | D53: 11894 | E53: 26.387 | F53: n/a | G53: n/a | H53: n/a | I53: n/a | J53: n/a | K53: n/a
A54: 51 | B54: Mini Golf Hole 7 | C54: 41.27 | D54: 11457 | E54: 11.981 | F54: n/a | G54: n/a | H54: n/a | I54: n/a | J54: n/a | K54: n/a
A55: 52 | B55: Mini Golf Hole 8 | C55: 45.28 | D55: 12163 | E55: 22.986 | F55: n/a | G55: n/a | H55: n/a | I55: n/a | J55: n/a | K55: n/a
A56: 53 | B56: Mini Golf Hole 9 | C56: 27.7 | D56: 8755 | E56: 12.806 | F56: n/a | G56: n/a | H56: n/a | I56: n/a | J56: n/a | K56: n/a

Sheet R21a_v5p0
B1: Contact Forces Tests | C1: 9.10.0.1602886 (R2021a) | F1: 07-Mar-2021 00:34:57 | H1: CFL v5.0
D2: Linear, No Friction | F2: Linear, Stick-Slip C | H2: Nonlin., No Friction | J2: Nonlin., Stick-Slip C
A3: # | B3: Model | C3: Stop Time | D3: # Steps | E3: Sim Time | F3: # Steps | G3: Sim Time | H3: # Steps | I3: Sim Time | J3: # Steps | K3: Sim Time
A4: 1 | B4: Collision_01_Ball_Infinite_Plane | C4: 6.00 | D4: 2401 | E4: 0.188 | F4: 2401 | G4: 0.131 | H4: 2401 | I4: 0.131 | J4: 2401 | K4: 0.125
A5: 2 | B5: Collision_02_Disk_Finite_Plane_Fixed | C5: 4.00 | D5: 669 | E5: 0.102 | F5: 935 | G5: 0.077 | H5: 718 | I5: 0.064 | J5: 1008 | K5: 0.083
A6: 3 | B6: Collision_03_Disk_Finite_Plane_Spin | C6: 1.50 | D6: 298 | E6: 0.075 | F6: 366 | G6: 0.044 | H6: 317 | I6: 0.038 | J6: 400 | K6: 0.046
A7: 4 | B7: Collision_04_Disks_in_Box | C7: 3.00 | D7: 3765 | E7: 1750 | F7: 4749 | G7: 2311 | H7: 5071 | I7: 2425 | J7: 6035 | K7: 3118
A8: 5 | B8: Collision_05_Disk_in_Ring | C8: 5.00 | D8: 2052 | E8: 0.207 | F8: 2639 | G8: 0.224 | H8: 2285 | I8: 0.208 | J8: 2949 | K8: 0.412
A9: 6 | B9: Collision_06_Catapult | C9: 1.20 | D9: 604 | E9: 0.163 | F9: 582 | G9: 0.108 | H9: 665 | I9: 0.112 | J9: 484 | K9: 0.094
A10: 7 | B10: Collision_07_Ball_Finite_Plane_Float | C10: 1.50 | D10: 210 | E10: 0.067 | F10: 213 | G10: 0.034 | H10: 222 | I10: 0.034 | J10: 225 | K10: 0.035
A11: 8 | B11: Collision_08_Compare_Forces | C11: 5.00 | D11: 9430 | E11: 2114 | F11: 18796 | G11: 4596 | H11: 11385 | I11: 2847 | J11: 20520 | K11: 5525
A12: 9 | B12: Friction_01_Box_on_Ramp_Constraint | C12: 10.00 | D12: 1137 | E12: 0.118 | F12: 1137 | G12: 0.063 | H12: 1137 | I12: 0.062 | J12: 1137 | K12: 0.062
A13: 10 | B13: Friction_02_Box_on_Ramp | C13: 10.00 | D13: 1313 | E13: 0.180 | F13: 1401 | G13: 0.173 | H13: 1398 | I13: 0.155 | J13: 1490 | K13: 0.198
A14: 11 | B14: Friction_03_Double_Pendulum_Constraint | C14: 45.00 | D14: 5535 | E14: 0.301 | F14: 5535 | G14: 0.467 | H14: 5535 | I14: 0.366 | J14: 5535 | K14: 0.342
A15: 12 | B15: Friction_04_Disk_Rolling_on_Ramp | C15: 4.00 | D15: 721 | E15: 0.129 | F15: 858 | G15: 0.076 | H15: 779 | I15: 0.068 | J15: 943 | K15: 0.086
A16: 13 | B16: Friction_05_Beam_on_Wheel | C16: 10.00 | D16: 1326 | E16: 0.136 | F16: 1402 | G16: 0.120 | H16: 1420 | I16: 0.110 | J16: 1478 | K16: 0.122
A17: 14 | B17: Friction_06_Disk_on_Disk | C17: 15.00 | D17: 6557 | E17: 1043 | F17: 6736 | G17: 1050 | H17: 5880 | I17: 0.967 | J17: 6338 | K17: 1118
A18: 15 | B18: Friction_07_Floating_Disks | C18: 2.00 | D18: 290 | E18: 0.096 | F18: 313 | G18: 0.053 | H18: 313 | I18: 0.054 | J18: 331 | K18: 0.060
A19: 16 | B19: Friction_08_Disks_and_Ring | C19: 30.00 | D19: 3473 | E19: 0.591 | F19: 3673 | G19: 0.556 | H19: 3576 | I19: 0.496 | J19: 3772 | K19: 0.591
A20: 17 | B20: Friction_09_Ring_on_Disk_Float | C20: 50.00 | D20: 7298 | E20: 0.853 | F20: 7174 | G20: 0.793 | H20: 98695 | I20: 8236 | J20: 99461 | K20: 8569
A21: 18 | B21: Friction_10_Ball_on_Wheel | C21: 30.00 | D21: 3713 | E21: 0.436 | F21: 4540 | G21: 0.462 | H21: 3980 | I21: 0.383 | J21: 4025 | K21: 0.371
A22: 19 | B22: sm_ball_bearing_testrig | C22: 10.00 | D22: 1540 | E22: 1755 | F22: 1540 | G22: 1627 | H22: 1540 | I22: 1582 | J22: 1540 | K22: 1578
A23: 20 | B23: Cam_Follower | C23: 15.00 | D23: 3162 | E23: 1098 | F23: 3114 | G23: 1056 | H23: 3753 | I23: 1159 | J23: 3701 | K23: 1185
A24: 21 | B24: Cam_Follower_Constraint | C24: 4.00 | D24: 252 | E24: 0.124 | F24: 252 | G24: 0.054 | H24: 252 | I24: 0.052 | J24: 252 | K24: 0.052
A25: 22 | B25: Geneva_Drive | C25: 30.00 | D25: 4705 | E25: 3014 | F25: 5132 | G25: 3430 | H25: 4543 | I25: 2985 | J25: 5114 | K25: 3435
A26: 23 | B26: Spinning_Boxes | C26: 12.00 | D26: 13158 | E26: 4929 | F26: 14604 | G26: 5283 | H26: 22897 | I26: 7911 | J26: 18415 | K26: 6739
A27: 24 | B27: Belts_01_Two_Belts | C27: 20.00 | D27: 3402 | E27: 2018 | F27: 3938 | G27: 2390 | H27: 3538 | I27: 1957 | J27: 4199 | K27: 2569
A28: 25 | B28: Coll3D_01_Ball_Plane_Fixed | C28: 7.50 | D28: 941 | E28: 0.151 | F28: 1018 | G28: 0.114 | H28: 967 | I28: 0.097 | J28: 1070 | K28: 0.123
